<robot name="scarecrow_robot">
  <link name="base_link">
    <!-- 로봇의 기본 링크 -->
  </link>

  <!-- 왼쪽 팔 조인트와 링크 -->
  <joint name="left_arm_joint" type="revolute">
    <parent link="base_link"/>
    <child link="left_arm_link"/>
    <origin xyz="0 0 1" rpy="0 0 0"/>
    <axis xyz="0 1 0"/>
    <limit effort="100.0" lower="-1.57" upper="1.57" velocity="1.0"/>
  </joint>

  <link name="left_arm_link">
    <inertial>
      <mass value="1.0"/>
      <origin xyz="0 0 0" rpy="0 0 0"/>
      <inertia ixx="0.01" ixy="0.0" ixz="0.0" iyy="0.01" iyz="0.0" izz="0.01"/>
    </inertial>
    <!-- 왼쪽 팔 링크 -->
  </link>

  <!-- 오른쪽 팔 조인트와 링크 -->
  <joint name="right_arm_joint" type="revolute">
    <parent link="base_link"/>
    <child link="right_arm_link"/>
    <origin xyz="0 0 1" rpy="0 0 0"/>
    <axis xyz="0 1 0"/>
    <limit effort="100.0" lower="-1.57" upper="1.57" velocity="1.0"/>
  </joint>

  <link name="right_arm_link">
    <inertial>
      <mass value="1.0"/>
      <origin xyz="0 0 0" rpy="0 0 0"/>
      <inertia ixx="0.01" ixy="0.0" ixz="0.0" iyy="0.01" iyz="0.0" izz="0.01"/>
    </inertial>
    <!-- 오른쪽 팔 링크 -->
  </link>

  <!-- 레이저 스캐너 추가 -->
  <link name="laser_link">
    <inertial>
      <mass value="0.1"/>
      <origin xyz="0 0 0" rpy="0 0 0"/>
      <inertia ixx="0.01" ixy="0.0" ixz="0.0" iyy="0.01" iyz="0.0" izz="0.01"/>
    </inertial>
    <visual>
      <geometry>
        <cylinder length="0.1" radius="0.02"/>
      </geometry>
      <origin xyz="0 0 0" rpy="0 0 0"/>
      <material name="blue">
        <color rgba="0.0 0.0 0.8 1.0"/>
      </material>
    </visual>
    <collision>
      <geometry>
        <cylinder length="0.1" radius="0.02"/>
      </geometry>
      <origin xyz="0 0 0" rpy="0 0 0"/>
    </collision>
  </link>

  <joint name="laser_joint" type="fixed">
    <parent link="base_link"/>
    <child link="laser_link"/>
    <origin xyz="0 0 1" rpy="0 0 0"/>
  </joint>

  <!-- Gazebo 플러그인 추가 -->
  <gazebo>
    <plugin name="gazebo_ros_control" filename="libgazebo_ros_control.so">
      <robotNamespace>/</robotNamespace>
    </plugin>
    <plugin name="gazebo_ros_laser" filename="libgazebo_ros_laser.so">
      <robotNamespace/>
      <frameName>laser_link</frameName>
      <topicName>/laser_scan</topicName>
      <gaussianNoise>0.01</gaussianNoise>
      <updateRate>10.0</updateRate>
      <ray>
        <scan>
          <horizontal>
            <samples>720</samples>
            <resolution>1</resolution>
            <min_angle>-1.57</min_angle>
            <max_angle>1.57</max_angle>
          </horizontal>
        </scan>
        <range>
          <min>0.0</min>
          <max>30.0</max>
        </range>
        <noise>
          <type>gaussian</type>
          <mean>0.0</mean>
          <stddev>0.01</stddev>
        </noise>
      </ray>
    </plugin>
  </gazebo>
</robot>
